<?xml version="1.0"?>
<!-- created with Phobos 0.7 -->
  <robot name="sherpa_ade">

    <link name="alpha_front_left">
      <inertial>
        <origin xyz="-0.006986 0.000189 -0.01829" rpy="0 0 0"/>
        <mass value="7.0"/>
        <inertia ixx="0.15214" ixy="0" ixz="0" iyy="0.15214" iyz="0" izz="0.026"/>
      </inertial>
      <visual name="vis_steeringPivot_front_left_HQ">
        <origin xyz="0 0 0" rpy="0 0 3.141591"/>
        <geometry>
          <mesh filename="../meshes/stl/steeringPivot.stl" scale="1.0 1.0 1.0"/>
        </geometry>
        <material name="mat_black"/>
      </visual>
      <collision name="col_steeringPivot_front_left">
        <origin xyz="-0.006986 0.000189 -0.01829" rpy="0 0 -1.5708"/>
        <geometry>
          <box size="0.166925 0.166925 0.473265"/>
        </geometry>
      </collision>
    </link>

    <link name="alpha_front_right">
      <inertial>
        <origin xyz="-0.005365 -0.00181 -0.01829" rpy="0 0 0"/>
        <mass value="7.0"/>
        <inertia ixx="0.15214" ixy="0" ixz="0" iyy="0.15214" iyz="0" izz="0.026"/>
      </inertial>
      <visual name="vis_steeringPivot_front_right_HQ">
        <origin xyz="0 0 0" rpy="0 0 -3.14159"/>
        <geometry>
          <mesh filename="../meshes/stl/steeringPivot.stl" scale="1.0 1.0 1.0"/>
        </geometry>
        <material name="mat_black"/>
      </visual>
      <collision name="col_steeringPivot_front_right">
        <origin xyz="-0.005365 -0.00181 -0.01829" rpy="0 0 0"/>
        <geometry>
          <box size="0.166925 0.166925 0.473265"/>
        </geometry>
      </collision>
    </link>

    <link name="alpha_rear_left">
      <inertial>
        <origin xyz="-0.009478 -0.002681 -0.01829" rpy="0 0 0"/>
        <mass value="7.0"/>
        <inertia ixx="0.15214" ixy="0" ixz="0" iyy="0.15214" iyz="0" izz="0.026"/>
      </inertial>
      <visual name="vis_steeringPivot_rear_left_HQ">
        <origin xyz="0 0 0" rpy="0 0 -3.141592"/>
        <geometry>
          <mesh filename="../meshes/stl/steeringPivot.stl" scale="1.0 1.0 1.0"/>
        </geometry>
        <material name="mat_black"/>
      </visual>
      <collision name="col_steeringPivot_rear_left">
        <origin xyz="-0.009478 -0.002681 -0.01829" rpy="0 0 3.141591"/>
        <geometry>
          <box size="0.166925 0.166925 0.473265"/>
        </geometry>
      </collision>
    </link>

    <link name="alpha_rear_right">
      <inertial>
        <origin xyz="-0.001633 -0.001921 -0.01829" rpy="0 0 0"/>
        <mass value="7.0"/>
        <inertia ixx="0.15214" ixy="0" ixz="0" iyy="0.15214" iyz="0" izz="0.026"/>
      </inertial>
      <visual name="vis_steeringPivot_rear_right_HQ">
        <origin xyz="0 0 0" rpy="0 0 3.141593"/>
        <geometry>
          <mesh filename="../meshes/stl/steeringPivot.stl" scale="1.0 1.0 1.0"/>
        </geometry>
        <material name="mat_black"/>
      </visual>
      <collision name="col_steeringPivot_rear_right">
        <origin xyz="-0.001633 -0.001922 -0.01829" rpy="0 0 1.570794"/>
        <geometry>
          <box size="0.166925 0.166925 0.473265"/>
        </geometry>
      </collision>
    </link>

    <link name="arm_joint_1">
      <inertial>
        <origin xyz="0.179429 0.003627 -0.169502" rpy="0 0 0"/>
        <mass value="10.26"/>
        <inertia ixx="0.14077" ixy="0.0461" ixz="0.02594" iyy="0.19733" iyz="-0.00066" izz="0.21665"/>
      </inertial>
      <visual name="vis_arm_01_HQ">
        <origin xyz="0.113341 -8e-06 -0.189131" rpy="3.141591 0 0"/>
        <geometry>
          <mesh filename="../meshes/stl/arm_1.stl" scale="1.0 1.0 1.0"/>
        </geometry>
        <material name="mat_grey"/>
      </visual>
      <collision name="col_arm_01">
        <origin xyz="0.103639 3.4e-05 -0.195527" rpy="-0.006636 -2.974552 -0.015571"/>
        <geometry>
          <box size="0.18491 0.121345 0.093212"/>
        </geometry>
      </collision>
      <collision name="col_arm_01.001">
        <origin xyz="0.102315 0.005077 -0.201941" rpy="1e-06 3.141593 -3e-06"/>
        <geometry>
          <box size="0.218354 0.150489 0.150489"/>
        </geometry>
      </collision>
      <collision name="col_arm_03">
        <origin xyz="0.223347 0.002512 -0.213764" rpy="1.570798 -2.356192 -1e-06"/>
        <geometry>
          <cylinder radius="0.054601" length="0.465452"/>
        </geometry>
      </collision>
    </link>

    <link name="arm_joint_2">
      <inertial>
        <origin xyz="0.376749 0.025168 6.4e-05" rpy="0 0 0"/>
        <mass value="2.654"/>
        <inertia ixx="0.00924" ixy="0" ixz="0" iyy="0.16418" iyz="0" izz="0.16418"/>
      </inertial>
      <visual name="vis_arm_04_HQ.002">
        <origin xyz="0.351909 0.00311 0.003035" rpy="1.570797 0 1.570796"/>
        <geometry>
          <mesh filename="../meshes/stl/arm_2.stl" scale="1.0 1.0 1.0"/>
        </geometry>
        <material name="mat_black"/>
      </visual>
      <collision name="col_arm_04">
        <origin xyz="0.376749 0.000275 6.4e-05" rpy="1.570797 0 1.570796"/>
        <geometry>
          <box size="0.062533 0.062533 0.812681"/>
        </geometry>
      </collision>
    </link>

    <link name="arm_joint_3">
      <inertial>
        <origin xyz="0.187553 -0.005446 -0.014289" rpy="0 0 0"/>
        <mass value="1.54"/>
        <inertia ixx="0.00311" ixy="0" ixz="0" iyy="0.03037" iyz="0" izz="0.03037"/>
      </inertial>
      <visual name="vis_arm_07_HQ">
        <origin xyz="0.044523 -0.011292 -0.010675" rpy="1.570796 0 1.570795"/>
        <geometry>
          <mesh filename="../meshes/stl/arm_3.stl" scale="1.0 1.0 1.0"/>
        </geometry>
        <material name="mat_black"/>
      </visual>
      <collision name="col_arm_06">
        <origin xyz="0 -0.001222 0.12057" rpy="0 0 1.570795"/>
        <geometry>
          <box size="0.086448 0.086448 0.128883"/>
        </geometry>
      </collision>
      <collision name="col_arm_07">
        <origin xyz="0.187553 -0.005446 -0.014289" rpy="1.570796 0 1.570795"/>
        <geometry>
          <box size="0.110078 0.110078 0.473846"/>
        </geometry>
      </collision>
    </link>

    <link name="arm_joint_4">
      <inertial>
        <origin xyz="-0.015755 -0.001749 0.131912" rpy="0 0 0"/>
        <mass value="3.75"/>
        <inertia ixx="0.04479" ixy="0" ixz="0" iyy="0.04479" iyz="0" izz="0.00808"/>
      </inertial>
      <visual name="visual_arm_4">
        <origin xyz="0.002894 0.016036 -0.167017" rpy="3.141592 0 -1.570796"/>
        <geometry>
          <mesh filename="../meshes/stl/arm_4.stl" scale="0.037466 0.037466 0.019117"/>
        </geometry>
        <material name="mat_black"/>
      </visual>
      <collision name="col_arm_09">
        <origin xyz="0.005384 -0.002446 -0.169296" rpy="8e-06 0 3.060205"/>
        <geometry>
          <box size="0.132332 0.132332 0.281157"/>
        </geometry>
      </collision>
    </link>

    <link name="arm_joint_5">
      <inertial>
        <origin xyz="0.092228 -0.00264 -0.015026" rpy="0 0 0"/>
        <mass value="2.16"/>
        <inertia ixx="0.01738" ixy="0" ixz="0" iyy="0.01738" iyz="0" izz="0.0063"/>
      </inertial>
      <visual name="visual_arm_5">
        <origin xyz="0.166222 -0.00203 -0.006678" rpy="0 1.570795 0"/>
        <geometry>
          <mesh filename="../meshes/stl/arm_5.stl" scale="0.037466 0.037466 0.019117"/>
        </geometry>
        <material name="mat_black"/>
      </visual>
      <collision name="col_arm_08">
        <origin xyz="0.131912 0.014395 -0.001481" rpy="1.570794 -1e-06 -1.570796"/>
        <geometry>
          <box size="0.113734 0.113734 0.361114"/>
        </geometry>
      </collision>
    </link>

    <link name="arm_joint_6">
      <inertial>
        <origin xyz="0 0 0" rpy="0 0 0"/>
        <mass value="0.001"/>
        <inertia ixx="0.001" ixy="0" ixz="0" iyy="0.001" iyz="0" izz="0.001"/>
      </inertial>
    </link>

    <link name="avionics_box_link">
      <inertial>
        <origin xyz="0 0 0" rpy="0 0 0"/>
        <mass value="16.0"/>
        <inertia ixx="0.440644" ixy="0" ixz="0" iyy="0.440644" iyz="0" izz="0.440644"/>
      </inertial>
      <visual name="vis_avionics_box">
        <origin xyz="0 0 0" rpy="0 0 0"/>
        <geometry>
          <mesh filename="../meshes/stl/Avionics_box.stl" scale="0.989723 1.059542 0.989723"/>
        </geometry>
      </visual>
      <collision name="col_avionics_box">
        <origin xyz="0 0 0" rpy="0 0 0"/>
        <geometry>
          <box size="0.287044 0.453858 0.415542"/>
        </geometry>
      </collision>
    </link>

    <link name="beta1_fake_front_left">
      <inertial>
        <origin xyz="0.0198 -0.077613 -1.1e-05" rpy="0 0 0"/>
        <mass value="3.3"/>
        <inertia ixx="0.02162" ixy="0" ixz="0" iyy="0.03008" iyz="0" izz="0.03008"/>
      </inertial>
      <visual name="vis_knee_front_left_HQ">
        <origin xyz="0 0 0" rpy="1.570796 2e-06 0"/>
        <geometry>
          <mesh filename="../meshes/stl/knee.stl" scale="1.0 1.0 1.0"/>
        </geometry>
        <material name="mat_black"/>
      </visual>
      <collision name="col_knee_front_left">
        <origin xyz="0.0198 -0.077613 -1.1e-05" rpy="0 1.570796 0"/>
        <geometry>
          <box size="0.198277 0.198277 0.264719"/>
        </geometry>
      </collision>
    </link>

    <link name="beta1_fake_front_right">
      <inertial>
        <origin xyz="0.0198 -0.077613 -1.1e-05" rpy="0 0 0"/>
        <mass value="3.3"/>
        <inertia ixx="0.02162" ixy="0" ixz="0" iyy="0.03008" iyz="0" izz="0.03008"/>
      </inertial>
      <visual name="vis_knee_front_right_HQ">
        <origin xyz="0 0 0" rpy="1.570796 -2e-06 0"/>
        <geometry>
          <mesh filename="../meshes/stl/knee.stl" scale="1.0 1.0 1.0"/>
        </geometry>
        <material name="mat_black"/>
      </visual>
      <collision name="col_knee_front_right">
        <origin xyz="0.0198 -0.077613 -1.1e-05" rpy="0 1.570796 0"/>
        <geometry>
          <box size="0.198277 0.198277 0.264719"/>
        </geometry>
      </collision>
    </link>

    <link name="beta1_fake_rear_left">
      <inertial>
        <origin xyz="0.0198 -0.077613 -1.1e-05" rpy="0 0 0"/>
        <mass value="3.3"/>
        <inertia ixx="0.02162" ixy="0" ixz="0" iyy="0.03008" iyz="0" izz="0.03008"/>
      </inertial>
      <visual name="vis_knee_rear_left_HQ">
        <origin xyz="0 0 0" rpy="1.570796 0 0"/>
        <geometry>
          <mesh filename="../meshes/stl/knee.stl" scale="1.0 1.0 1.0"/>
        </geometry>
        <material name="mat_black"/>
      </visual>
      <collision name="col_knee_rear_left">
        <origin xyz="0.0198 -0.077613 -1.1e-05" rpy="0 1.570796 0"/>
        <geometry>
          <box size="0.198277 0.198277 0.264719"/>
        </geometry>
      </collision>
    </link>

    <link name="beta1_fake_rear_right">
      <inertial>
        <origin xyz="0.0198 -0.077613 -1.1e-05" rpy="0 0 0"/>
        <mass value="3.3"/>
        <inertia ixx="0.02162" ixy="0" ixz="0" iyy="0.03008" iyz="0" izz="0.03008"/>
      </inertial>
      <visual name="vis_knee_rear_right_HQ">
        <origin xyz="0 0 0" rpy="1.570796 0 0"/>
        <geometry>
          <mesh filename="../meshes/stl/knee.stl" scale="1.0 1.0 1.0"/>
        </geometry>
        <material name="mat_black"/>
      </visual>
      <collision name="col_knee_rear_right">
        <origin xyz="0.0198 -0.077613 -1.1e-05" rpy="0 1.570796 0"/>
        <geometry>
          <box size="0.198277 0.198277 0.264718"/>
        </geometry>
      </collision>
    </link>

    <link name="beta2_fake_front_left">
      <inertial>
        <origin xyz="0.223201 -0.017873 2.2e-05" rpy="0 0 0"/>
        <mass value="1.56"/>
        <inertia ixx="0.002" ixy="0" ixz="0" iyy="0.01089" iyz="0" izz="0.00912"/>
      </inertial>
      <visual name="vis_innerLegInt_front_left_HQ">
        <origin xyz="0 0 0" rpy="1.570796 2e-06 0"/>
        <geometry>
          <mesh filename="../meshes/stl/innerLegInt.stl" scale="1.0 1.0 1.0"/>
        </geometry>
        <material name="Yellow"/>
      </visual>
      <collision name="col_innerLegInt_front_left">
        <origin xyz="0.223201 -0.017873 2.2e-05" rpy="0 0 0"/>
        <geometry>
          <box size="0.263211 0.029911 0.12025"/>
        </geometry>
      </collision>
    </link>

    <link name="beta2_fake_front_right">
      <inertial>
        <origin xyz="0.223201 -0.017874 2.2e-05" rpy="0 0 0"/>
        <mass value="1.56"/>
        <inertia ixx="0.002" ixy="0" ixz="0" iyy="0.01089" iyz="0" izz="0.00912"/>
      </inertial>
      <visual name="vis_innerLegInt_front_right_HQ">
        <origin xyz="0 0 0" rpy="1.570796 -2e-06 0"/>
        <geometry>
          <mesh filename="../meshes/stl/innerLegInt.stl" scale="1.0 1.0 1.0"/>
        </geometry>
        <material name="Yellow"/>
      </visual>
      <collision name="col_innerLegInt_front_right">
        <origin xyz="0.223201 -0.017873 2.2e-05" rpy="0 0 0"/>
        <geometry>
          <box size="0.263211 0.029911 0.12025"/>
        </geometry>
      </collision>
    </link>

    <link name="beta2_fake_rear_left">
      <inertial>
        <origin xyz="0.223201 -0.017873 2.1e-05" rpy="0 0 0"/>
        <mass value="1.56"/>
        <inertia ixx="0.002" ixy="0" ixz="0" iyy="0.01089" iyz="0" izz="0.00912"/>
      </inertial>
      <visual name="vis_innerLegInt_rear_left_HQ">
        <origin xyz="0 0 0" rpy="1.570796 0 0"/>
        <geometry>
          <mesh filename="../meshes/stl/innerLegInt.stl" scale="1.0 1.0 1.0"/>
        </geometry>
        <material name="Yellow"/>
      </visual>
      <collision name="col_innerLegInt_rear_left">
        <origin xyz="0.223201 -0.017873 2.1e-05" rpy="0 0 0"/>
        <geometry>
          <box size="0.263211 0.029911 0.12025"/>
        </geometry>
      </collision>
    </link>

    <link name="beta2_fake_rear_right">
      <inertial>
        <origin xyz="0.223201 -0.017873 2.2e-05" rpy="0 0 0"/>
        <mass value="1.56"/>
        <inertia ixx="0.002" ixy="0" ixz="0" iyy="0.01089" iyz="0" izz="0.00912"/>
      </inertial>
      <visual name="vis_innerLegInt_rear_right_HQ">
        <origin xyz="0 0 0" rpy="1.570796 0 0"/>
        <geometry>
          <mesh filename="../meshes/stl/innerLegInt.stl" scale="1.0 1.0 1.0"/>
        </geometry>
        <material name="Yellow"/>
      </visual>
      <collision name="col_innerLegInt_rear_right">
        <origin xyz="0.223201 -0.017873 2.2e-05" rpy="0 0 0"/>
        <geometry>
          <box size="0.263211 0.029911 0.12025"/>
        </geometry>
      </collision>
    </link>

    <link name="beta_front_left">
      <inertial>
        <origin xyz="0.176404 -0.000386 -5.8e-05" rpy="0 0 0"/>
        <mass value="1.01"/>
        <inertia ixx="0.00176" ixy="0" ixz="0" iyy="0.0111" iyz="0" izz="0.00957"/>
      </inertial>
      <visual name="vis_innerStrut_front_left_HQ">
        <origin xyz="0 0 0" rpy="1.570796 2e-06 0"/>
        <geometry>
          <mesh filename="../meshes/stl/innerStrut.stl" scale="1.0 1.0 1.0"/>
        </geometry>
        <material name="Yellow"/>
      </visual>
      <collision name="col_innerStrut_front_left">
        <origin xyz="0.176404 -0.000386 -5.8e-05" rpy="3.141592 2e-06 0"/>
        <geometry>
          <box size="0.335161 0.036553 0.13977"/>
        </geometry>
      </collision>
      <collision name="col_innerStrut_front_left.001">
        <origin xyz="0.132979 -0.086074 0.014001" rpy="3.141592 2e-06 0"/>
        <geometry>
          <box size="0.591306 0.176462 0.13977"/>
        </geometry>
      </collision>
    </link>

    <link name="beta_front_right">
      <inertial>
        <origin xyz="0.176404 -0.000386 -5.8e-05" rpy="0 0 0"/>
        <mass value="1.01"/>
        <inertia ixx="0.00176" ixy="0" ixz="0" iyy="0.0111" iyz="0" izz="0.00957"/>
      </inertial>
      <visual name="vis_innerStrut_front_right_HQ">
        <origin xyz="0 0 0" rpy="1.570796 -2e-06 0"/>
        <geometry>
          <mesh filename="../meshes/stl/innerStrut.stl" scale="1.0 1.0 1.0"/>
        </geometry>
        <material name="Yellow"/>
      </visual>
      <collision name="col_innerStrut_front_right">
        <origin xyz="0.176404 -0.000386 -5.8e-05" rpy="3.141592 -2e-06 0"/>
        <geometry>
          <box size="0.335161 0.036553 0.13977"/>
        </geometry>
      </collision>
      <collision name="col_innerStrut_front_right.001">
        <origin xyz="0.119702 -0.086074 -0.00084" rpy="3.141592 -2e-06 0"/>
        <geometry>
          <box size="0.591306 0.176462 0.13977"/>
        </geometry>
      </collision>
    </link>

    <link name="beta_rear_left">
      <inertial>
        <origin xyz="0.176404 -0.000386 -5.9e-05" rpy="0 0 0"/>
        <mass value="1.01"/>
        <inertia ixx="0.00176" ixy="0" ixz="0" iyy="0.0111" iyz="0" izz="0.00957"/>
      </inertial>
      <visual name="vis_innerStrut_rear_left_HQ">
        <origin xyz="0 0 0" rpy="1.570796 0 0"/>
        <geometry>
          <mesh filename="../meshes/stl/innerStrut.stl" scale="1.0 1.0 1.0"/>
        </geometry>
        <material name="Yellow"/>
      </visual>
      <collision name="col_innerStrut_rear_left">
        <origin xyz="0.176404 -0.000386 -5.9e-05" rpy="3.141592 0 0"/>
        <geometry>
          <box size="0.335161 0.036553 0.13977"/>
        </geometry>
      </collision>
      <collision name="col_innerStrut_rear_left.001">
        <origin xyz="0.147819 -0.086074 0.000722" rpy="3.141592 0 1e-06"/>
        <geometry>
          <box size="0.591306 0.176462 0.13977"/>
        </geometry>
      </collision>
    </link>

    <link name="beta_rear_right">
      <inertial>
        <origin xyz="0.176403 -0.000386 -5.8e-05" rpy="0 0 0"/>
        <mass value="1.01"/>
        <inertia ixx="0.00176" ixy="0" ixz="0" iyy="0.0111" iyz="0" izz="0.00957"/>
      </inertial>
      <visual name="vis_innerStrut_rear_right_HQ">
        <origin xyz="0.000497 0.000497 0" rpy="1.570796 0 0"/>
        <geometry>
          <mesh filename="../meshes/stl/innerStrut.stl" scale="1.0 1.0 1.0"/>
        </geometry>
        <material name="Yellow"/>
      </visual>
      <collision name="col_innerStrut_rear_right">
        <origin xyz="0.176403 -0.000386 -5.8e-05" rpy="3.141592 0 0"/>
        <geometry>
          <box size="0.335161 0.036553 0.13977"/>
        </geometry>
      </collision>
      <collision name="col_innerStrut_rear_right.001">
        <origin xyz="0.13454 -0.086074 -0.014116" rpy="3.141592 1e-06 0"/>
        <geometry>
          <box size="0.591306 0.176462 0.13977"/>
        </geometry>
      </collision>
    </link>

    <link name="endeffector_camera">
      <inertial>
        <origin xyz="0 0 0" rpy="0 0 0"/>
        <mass value="0.001"/>
        <inertia ixx="0.001" ixy="0" ixz="0" iyy="0.001" iyz="0" izz="0.001"/>
      </inertial>
    </link>

    <link name="gamma1_fake_front_left">
      <inertial>
        <origin xyz="0.050151 -0.016648 0" rpy="0 0 0"/>
        <mass value="2.22"/>
        <inertia ixx="0.01802" ixy="0" ixz="0" iyy="0.01248" iyz="0" izz="0.01802"/>
      </inertial>
      <visual name="vis_steeringUnit_1_front_left_HQ">
        <origin xyz="0 0 0" rpy="1.570796 2e-06 0"/>
        <geometry>
          <mesh filename="../meshes/stl/steeringUnit_top.stl" scale="1.0 1.0 1.0"/>
        </geometry>
        <material name="mat_black"/>
      </visual>
      <collision name="col_steeringUnit_front_left">
        <origin xyz="0.050151 -0.016648 0" rpy="1.570796 0 0"/>
        <geometry>
          <box size="0.183671 0.183671 0.252377"/>
        </geometry>
      </collision>
    </link>

    <link name="gamma1_fake_front_right">
      <inertial>
        <origin xyz="0.050151 -0.016648 0" rpy="0 0 0"/>
        <mass value="2.22"/>
        <inertia ixx="0.01802" ixy="0" ixz="0" iyy="0.01248" iyz="0" izz="0.01802"/>
      </inertial>
      <visual name="vis_steeringUnit_1_front_right_HQ">
        <origin xyz="0 0 0" rpy="1.570796 -2e-06 0"/>
        <geometry>
          <mesh filename="../meshes/stl/steeringUnit_top.stl" scale="1.0 1.0 1.0"/>
        </geometry>
        <material name="mat_black"/>
      </visual>
      <collision name="col_steeringUnit_front_right">
        <origin xyz="0.050151 -0.016648 0" rpy="1.570796 0 0"/>
        <geometry>
          <box size="0.183671 0.183671 0.252377"/>
        </geometry>
      </collision>
    </link>

    <link name="gamma1_fake_rear_left">
      <inertial>
        <origin xyz="0.050151 -0.016648 0" rpy="0 0 0"/>
        <mass value="2.22"/>
        <inertia ixx="0.01802" ixy="0" ixz="0" iyy="0.01248" iyz="0" izz="0.01802"/>
      </inertial>
      <visual name="vis_steeringUnit_1_rear_left_HQ">
        <origin xyz="0 0 0" rpy="1.570796 0 0"/>
        <geometry>
          <mesh filename="../meshes/stl/steeringUnit_top.stl" scale="1.0 1.0 1.0"/>
        </geometry>
        <material name="mat_black"/>
      </visual>
      <collision name="col_steeringUnit_rear_left">
        <origin xyz="0.050151 -0.016648 0" rpy="1.570796 0 0"/>
        <geometry>
          <box size="0.183671 0.183671 0.252377"/>
        </geometry>
      </collision>
    </link>

    <link name="gamma1_fake_rear_right">
      <inertial>
        <origin xyz="0.050151 -0.016648 2e-06" rpy="0 0 0"/>
        <mass value="2.22"/>
        <inertia ixx="0.01964" ixy="0" ixz="0" iyy="0.0136" iyz="0" izz="0.01964"/>
      </inertial>
      <visual name="vis_steeringUnit_1_rear_right_HQ">
        <origin xyz="0 0 0" rpy="1.570796 0 0"/>
        <geometry>
          <mesh filename="../meshes/stl/steeringUnit_top.stl" scale="1.0 1.0 1.0"/>
        </geometry>
        <material name="mat_black"/>
      </visual>
      <collision name="col_steeringUnit_rear_right">
        <origin xyz="0.050151 -0.016648 2e-06" rpy="1.570794 0 0"/>
        <geometry>
          <box size="0.19171 0.19171 0.263422"/>
        </geometry>
      </collision>
    </link>

    <link name="gamma2_fake_front_left">
      <inertial>
        <origin xyz="0.131482 -0.001015 0.000139" rpy="0 0 0"/>
        <mass value="0.87"/>
        <inertia ixx="0.00049" ixy="0" ixz="0" iyy="0.00416" iyz="0" izz="0.00379"/>
      </inertial>
      <visual name="vis_outerLegInt_front_left_HQ">
        <origin xyz="0 0 0" rpy="1.570796 2e-06 -0.13055"/>
        <geometry>
          <mesh filename="../meshes/stl/outerLegInt.stl" scale="1.0 1.0 1.0"/>
        </geometry>
        <material name="Yellow"/>
      </visual>
      <collision name="col_outerLegInt_front_left">
        <origin xyz="0.131482 -0.001015 0.000139" rpy="0 0 0"/>
        <geometry>
          <box size="0.226682 0.028797 0.077146"/>
        </geometry>
      </collision>
    </link>

    <link name="gamma2_fake_front_right">
      <inertial>
        <origin xyz="0.131484 -0.001015 0.000139" rpy="0 0 0"/>
        <mass value="0.87"/>
        <inertia ixx="0.00049" ixy="0" ixz="0" iyy="0.00416" iyz="0" izz="0.00379"/>
      </inertial>
      <visual name="vis_outerLegInt_front_right_HQ">
        <origin xyz="0 0 0" rpy="1.570796 -2e-06 -0.13055"/>
        <geometry>
          <mesh filename="../meshes/stl/outerLegInt.stl" scale="1.0 1.0 1.0"/>
        </geometry>
        <material name="Yellow"/>
      </visual>
      <collision name="col_outerLegInt_front_right">
        <origin xyz="0.131483 -0.001015 0.000139" rpy="0 0 0"/>
        <geometry>
          <box size="0.226681 0.028797 0.077146"/>
        </geometry>
      </collision>
    </link>

    <link name="gamma2_fake_rear_left">
      <inertial>
        <origin xyz="0.131481 -0.001014 0.000139" rpy="0 0 0"/>
        <mass value="0.87"/>
        <inertia ixx="0.00049" ixy="0" ixz="0" iyy="0.00416" iyz="0" izz="0.00379"/>
      </inertial>
      <visual name="vis_outerLegInt_rear_left_HQ">
        <origin xyz="0 0 0" rpy="1.570796 0 -0.13055"/>
        <geometry>
          <mesh filename="../meshes/stl/outerLegInt.stl" scale="1.0 1.0 1.0"/>
        </geometry>
        <material name="Yellow"/>
      </visual>
      <collision name="col_outerLegInt_rear_left">
        <origin xyz="0.131481 -0.001014 0.000139" rpy="0 1e-06 2e-06"/>
        <geometry>
          <box size="0.226681 0.028797 0.077146"/>
        </geometry>
      </collision>
    </link>

    <link name="gamma2_fake_rear_right">
      <inertial>
        <origin xyz="0.11467 -0.007201 0.000139" rpy="0 0 0"/>
        <mass value="0.87"/>
        <inertia ixx="0.00049" ixy="8e-05" ixz="0" iyy="0.00416" iyz="0" izz="0.00379"/>
      </inertial>
      <visual name="vis_outerLegInt_rear_right_HQ">
        <origin xyz="0 0 0" rpy="1.570796 0 -0.13055"/>
        <geometry>
          <mesh filename="../meshes/stl/outerLegInt.stl" scale="1.0 1.0 1.0"/>
        </geometry>
        <material name="Yellow"/>
      </visual>
      <collision name="col_outerLegInt_rear_right">
        <origin xyz="0.11467 -0.007201 0.000138" rpy="0 0 0.022082"/>
        <geometry>
          <box size="0.226681 0.028797 0.077146"/>
        </geometry>
      </collision>
    </link>

    <link name="gamma_front_left">
      <inertial>
        <origin xyz="0.198416 0.02835 1e-05" rpy="0 0 0"/>
        <mass value="0.92"/>
        <inertia ixx="0.00076" ixy="0.00107" ixz="0" iyy="0.00876" iyz="0" izz="0.00843"/>
      </inertial>
      <visual name="vis_outerStrut_front_left_HQ">
        <origin xyz="-9e-06 0 0" rpy="1.570796 2e-06 -0.009723"/>
        <geometry>
          <mesh filename="../meshes/stl/outerStrut.stl" scale="1.0 1.0 1.0"/>
        </geometry>
        <material name="Yellow"/>
      </visual>
      <collision name="col_outerStrut_front_left">
        <origin xyz="0.198416 0.02835 1e-05" rpy="0 0 0.13055"/>
        <geometry>
          <box size="0.330161 0.031135 0.084114"/>
        </geometry>
      </collision>
      <collision name="col_outerStrut_front_left.001">
        <origin xyz="0.251699 -0.036166 1e-05" rpy="0 0 0.13055"/>
        <geometry>
          <box size="0.511872 0.15966 0.103487"/>
        </geometry>
      </collision>
    </link>

    <link name="gamma_front_right">
      <inertial>
        <origin xyz="0.198416 0.02835 9e-06" rpy="0 0 0"/>
        <mass value="0.92"/>
        <inertia ixx="0.00076" ixy="0.00107" ixz="0" iyy="0.00876" iyz="0" izz="0.00843"/>
      </inertial>
      <visual name="vis_outerStrut_front_right_HQ">
        <origin xyz="-9e-06 2e-06 0" rpy="1.570796 -2e-06 0"/>
        <geometry>
          <mesh filename="../meshes/stl/outerStrut.stl" scale="1.0 1.0 1.0"/>
        </geometry>
        <material name="Yellow"/>
      </visual>
      <collision name="col_outerStrut_front_right">
        <origin xyz="0.198416 0.02835 1e-05" rpy="0 0 0.13055"/>
        <geometry>
          <box size="0.330161 0.031135 0.084114"/>
        </geometry>
      </collision>
      <collision name="col_outerStrut_front_right.001">
        <origin xyz="0.251697 -0.036166 1e-05" rpy="0 0 0.13055"/>
        <geometry>
          <box size="0.511872 0.15966 0.103487"/>
        </geometry>
      </collision>
    </link>

    <link name="gamma_rear_left">
      <inertial>
        <origin xyz="0.198416 0.02835 9e-06" rpy="0 0 0"/>
        <mass value="0.92"/>
        <inertia ixx="0.00076" ixy="0.00107" ixz="0" iyy="0.00876" iyz="0" izz="0.00843"/>
      </inertial>
      <visual name="vis_outerStrut_rear_left_HQ">
        <origin xyz="-3e-06 4e-06 0" rpy="1.570796 0 -0.010392"/>
        <geometry>
          <mesh filename="../meshes/stl/outerStrut.stl" scale="1.0 1.0 1.0"/>
        </geometry>
        <material name="Yellow"/>
      </visual>
      <collision name="col_outerStrut_rear_left">
        <origin xyz="0.198416 0.02835 9e-06" rpy="0 0 0.13055"/>
        <geometry>
          <box size="0.33016 0.031135 0.084114"/>
        </geometry>
      </collision>
      <collision name="col_outerStrut_rear_left.001">
        <origin xyz="0.251697 -0.036166 8e-06" rpy="3e-06 -1e-06 0.130549"/>
        <geometry>
          <box size="0.511872 0.15966 0.103487"/>
        </geometry>
      </collision>
    </link>

    <link name="gamma_rear_right">
      <inertial>
        <origin xyz="0.201266 0.030127 1e-05" rpy="0 0 0"/>
        <mass value="0.92"/>
        <inertia ixx="0.00072" ixy="0.0009" ixz="0" iyy="0.0088" iyz="0" izz="0.00843"/>
      </inertial>
      <visual name="vis_outerStrut_rear_right_HQ">
        <origin xyz="-5e-06 4e-06 0" rpy="1.570796 0 -0.010483"/>
        <geometry>
          <mesh filename="../meshes/stl/outerStrut.stl" scale="1.0 1.0 1.0"/>
        </geometry>
        <material name="Yellow"/>
      </visual>
      <collision name="col_outerStrut_rear_right">
        <origin xyz="0.201266 0.030127 1e-05" rpy="0 0 0.10933"/>
        <geometry>
          <box size="0.33016 0.031135 0.084114"/>
        </geometry>
      </collision>
      <collision name="col_outerStrut_rear_right.001">
        <origin xyz="0.256496 -0.035276 1.2e-05" rpy="-1e-06 0 0.10933"/>
        <geometry>
          <box size="0.500205 0.160294 0.103487"/>
        </geometry>
      </collision>
    </link>

    <link name="generator_link">
      <inertial>
        <origin xyz="0.09043 0.004012 -0.042291" rpy="0 0 0"/>
        <mass value="15.0"/>
        <inertia ixx="54.247096" ixy="0" ixz="1e-06" iyy="31.588076" iyz="0" izz="40.673559"/>
      </inertial>
      <visual name="vis_generator">
        <origin xyz="0 0 0" rpy="1.56556 -0.000819 1.571639"/>
        <geometry>
          <mesh filename="../meshes/stl/generator.stl" scale="0.001098 0.001098 0.001057"/>
        </geometry>
        <material name="red"/>
      </visual>
      <visual name="vis_generator baseplate">
        <origin xyz="0.497025 -0.298623 -0.284298" rpy="1.56556 -0.000819 1.570796"/>
        <geometry>
          <mesh filename="../meshes/stl/generator baseplate.stl" scale="0.001031 0.001062 0.000867"/>
        </geometry>
      </visual>
      <collision name="col_generator">
        <origin xyz="0.005436 1.4e-05 -0.083165" rpy="1.565561 -0.000819 1.57164"/>
        <geometry>
          <box size="0.475145 0.347196 0.255688"/>
        </geometry>
      </collision>
    </link>

    <link name="gps_antenna_link">
      <inertial>
        <origin xyz="0 0 0" rpy="0 0 0"/>
        <mass value="0.001"/>
        <inertia ixx="0.001" ixy="0" ixz="0" iyy="0.001" iyz="0" izz="0.001"/>
      </inertial>
      <visual name="vis_gps_antenna_base">
        <origin xyz="0 0 0" rpy="0 0 0"/>
        <geometry>
          <mesh filename="../meshes/stl/gps_antenna_base.stl" scale="0.001087 0.000481 0.000938"/>
        </geometry>
        <material name="mat_grey"/>
      </visual>
      <collision name="col_gps_antenna_base">
        <origin xyz="0 0 0" rpy="0 0 0"/>
        <geometry>
          <box size="0.055647 1.313208 0.022836"/>
        </geometry>
      </collision>
    </link>

    <link name="imu">
      <inertial>
        <origin xyz="0 0 0" rpy="0 0 0"/>
        <mass value="0.001"/>
        <inertia ixx="0.001" ixy="0" ixz="0" iyy="0.001" iyz="0" izz="0.001"/>
      </inertial>
    </link>

    <link name="joint_velodyne">
      <inertial>
        <origin xyz="0 0 0" rpy="0 0 0"/>
        <mass value="0.001"/>
        <inertia ixx="0.001" ixy="0" ixz="0" iyy="0.001" iyz="0" izz="0.001"/>
      </inertial>
    </link>

    <link name="link_force_torque_sensor_link_front_left">
      <inertial>
        <origin xyz="0 0 0" rpy="0 0 0"/>
        <mass value="0.001"/>
        <inertia ixx="0.001" ixy="0" ixz="0" iyy="0.001" iyz="0" izz="0.001"/>
      </inertial>
    </link>

    <link name="link_force_torque_sensor_link_front_right">
      <inertial>
        <origin xyz="0 0 0" rpy="0 0 0"/>
        <mass value="0.001"/>
        <inertia ixx="0.001" ixy="0" ixz="0" iyy="0.001" iyz="0" izz="0.001"/>
      </inertial>
    </link>

    <link name="link_force_torque_sensor_link_rear_left">
      <inertial>
        <origin xyz="0 0 0" rpy="0 0 0"/>
        <mass value="0.001"/>
        <inertia ixx="0.001" ixy="0" ixz="0" iyy="0.001" iyz="0" izz="0.001"/>
      </inertial>
    </link>

    <link name="link_force_torque_sensor_link_rear_right">
      <inertial>
        <origin xyz="0 0 0" rpy="0 0 0"/>
        <mass value="0.001"/>
        <inertia ixx="0.001" ixy="0" ixz="0" iyy="0.001" iyz="0" izz="0.001"/>
      </inertial>
    </link>

    <link name="link_ft_arm">
      <inertial>
        <origin xyz="-0.000603 -0.001465 0.033618" rpy="0 0 0"/>
        <mass value="2.14"/>
        <inertia ixx="0.00542" ixy="0" ixz="0" iyy="0.00542" iyz="0" izz="0.00846"/>
      </inertial>
      <visual name="visual_arm_6">
        <origin xyz="-0.000583 -0.0009 0.054591" rpy="0 0 0"/>
        <geometry>
          <mesh filename="../meshes/stl/arm_adapter.stl" scale="0.076901 0.076901 0.018862"/>
        </geometry>
        <material name="mat_black"/>
      </visual>
      <collision name="col_arm_10">
        <origin xyz="-0.000603 -0.001465 0.033618" rpy="0 0 0"/>
        <geometry>
          <box size="0.153978 0.153978 0.081689"/>
        </geometry>
      </collision>
    </link>

    <link name="link_gps_antenna_1">
      <inertial>
        <origin xyz="0 0 0" rpy="0 0 0"/>
        <mass value="0.001"/>
        <inertia ixx="0.001" ixy="0" ixz="0" iyy="0.001" iyz="0" izz="0.001"/>
      </inertial>
      <visual name="vis_gps_antenna1">
        <origin xyz="0 0 0" rpy="0 0 -3.141593"/>
        <geometry>
          <mesh filename="../meshes/stl/antenna2.stl" scale="-0.04771 -0.04771 -0.04771"/>
        </geometry>
        <material name="Orange.003"/>
      </visual>
      <collision name="col_gps_antenna1">
        <origin xyz="0 0 0" rpy="0 0 -3.141593"/>
        <geometry>
          <box size="0.119275 0.119275 0.023855"/>
        </geometry>
      </collision>
    </link>

    <link name="link_gps_antenna_2">
      <inertial>
        <origin xyz="0 0 0" rpy="0 0 0"/>
        <mass value="0.001"/>
        <inertia ixx="0.001" ixy="0" ixz="0" iyy="0.001" iyz="0" izz="0.001"/>
      </inertial>
      <visual name="vis_gps_antenna2">
        <origin xyz="0 0 0" rpy="0 0 -3.141593"/>
        <geometry>
          <mesh filename="../meshes/stl/antenna1.stl" scale="-0.04771 -0.04771 -0.04771"/>
        </geometry>
        <material name="Orange.004"/>
      </visual>
      <collision name="col_gps_antenna2">
        <origin xyz="0 0 0" rpy="0 0 -3.141593"/>
        <geometry>
          <box size="0.119275 0.119275 0.023855"/>
        </geometry>
      </collision>
    </link>

    <link name="link_mast_box">
      <inertial>
        <origin xyz="0 0 0" rpy="0 0 0"/>
        <mass value="0.001"/>
        <inertia ixx="0.001" ixy="0" ixz="0" iyy="0.001" iyz="0" izz="0.001"/>
      </inertial>
      <visual name="vis_mast_box">
        <origin xyz="0 0 0" rpy="0 0 0"/>
        <geometry>
          <mesh filename="../meshes/stl/mast_box.stl" scale="0.989723 0.974624 0.989723"/>
        </geometry>
      </visual>
      <collision name="col_mast_box">
        <origin xyz="3e-06 0 3e-06" rpy="0 0 0"/>
        <geometry>
          <box size="0.10012 0.147291 0.208702"/>
        </geometry>
      </collision>
    </link>

    <link name="link_mastcam_fixed_cameras">
      <inertial>
        <origin xyz="0 0 0" rpy="0 0 0"/>
        <mass value="0.001"/>
        <inertia ixx="0.001" ixy="0" ixz="0" iyy="0.001" iyz="0" izz="0.001"/>
      </inertial>
      <visual name="vis_mastcam_fixed_camera_bench">
        <origin xyz="0 0 0" rpy="0 0 0"/>
        <geometry>
          <mesh filename="../meshes/stl/mastcam_fixed_camera_bench.stl" scale="0.989723 0.974624 0.989723"/>
        </geometry>
      </visual>
    </link>

    <link name="link_mastcam_fixed_left">
      <inertial>
        <origin xyz="0 0 0" rpy="0 0 0"/>
        <mass value="0.001"/>
        <inertia ixx="0.001" ixy="0" ixz="0" iyy="0.001" iyz="0" izz="0.001"/>
      </inertial>
      <visual name="vis_mastcam_fixed_left_camera">
        <origin xyz="0 0 0" rpy="0 0 0"/>
        <geometry>
          <mesh filename="../meshes/stl/mastcam_fixed_left_camera.stl" scale="0.989723 0.974624 0.989723"/>
        </geometry>
      </visual>
      <collision name="col_mastcam_fixed_left_camera">
        <origin xyz="0 0 0" rpy="0 0.65535 0"/>
        <geometry>
          <box size="0.123525 0.057905 0.05204"/>
        </geometry>
      </collision>
    </link>

    <link name="link_mastcam_fixed_right">
      <inertial>
        <origin xyz="0 0 0" rpy="0 0 0"/>
        <mass value="0.001"/>
        <inertia ixx="0.001" ixy="0" ixz="0" iyy="0.001" iyz="0" izz="0.001"/>
      </inertial>
      <visual name="vis_mastcam_fixed_right_camera">
        <origin xyz="0 0 0" rpy="0 0 0"/>
        <geometry>
          <mesh filename="../meshes/stl/mastcam_fixed_right_camera.stl" scale="0.989723 0.974624 0.989723"/>
        </geometry>
      </visual>
      <collision name="col_mastcam_fixed_right_camera">
        <origin xyz="0 0 0" rpy="0 0.65535 0"/>
        <geometry>
          <box size="0.123525 0.057905 0.05204"/>
        </geometry>
      </collision>
    </link>

    <link name="link_mastcam_ptu_left">
      <inertial>
        <origin xyz="0 0 0" rpy="0 0 0"/>
        <mass value="0.001"/>
        <inertia ixx="0.001" ixy="0" ixz="0" iyy="0.001" iyz="0" izz="0.001"/>
      </inertial>
      <visual name="vis_mastcam_ptu_left_camera">
        <origin xyz="-0.057208 -0.016864 -0.000345" rpy="0 0 0"/>
        <geometry>
          <mesh filename="../meshes/stl/mastcam_ptu_left_camera.stl" scale="0.989723 0.974624 0.989723"/>
        </geometry>
      </visual>
      <collision name="col_mastcam_ptu_left_camera">
        <origin xyz="-0.056906 -0.016864 -0.000345" rpy="0 0 0"/>
        <geometry>
          <box size="0.12593 0.058374 0.062455"/>
        </geometry>
      </collision>
    </link>

    <link name="link_mastcam_ptu_right">
      <inertial>
        <origin xyz="0 0 0" rpy="0 0 0"/>
        <mass value="0.001"/>
        <inertia ixx="0.001" ixy="0" ixz="0" iyy="0.001" iyz="0" izz="0.001"/>
      </inertial>
      <visual name="vis_mastcam_ptu_right_camera">
        <origin xyz="-0.056042 -0.016865 -0.000347" rpy="0 0 0"/>
        <geometry>
          <mesh filename="../meshes/stl/mastcam_ptu_right_camera.stl" scale="0.989723 0.974624 0.989723"/>
        </geometry>
      </visual>
      <collision name="col_mastcam_ptu_right_camera">
        <origin xyz="-0.05471 -0.016865 -0.000347" rpy="0 0 0"/>
        <geometry>
          <box size="0.12593 0.058374 0.062455"/>
        </geometry>
      </collision>
    </link>

    <link name="link_mastcam_thermal_infrared">
      <inertial>
        <origin xyz="0 0 0" rpy="0 0 0"/>
        <mass value="0.001"/>
        <inertia ixx="0.001" ixy="0" ixz="0" iyy="0.001" iyz="0" izz="0.001"/>
      </inertial>
      <visual name="vis_mastcam_thermal_infrared_camera">
        <origin xyz="-0.040582 0 0.010122" rpy="0 0 0"/>
        <geometry>
          <mesh filename="../meshes/stl/thermal_infrared_camera.stl" scale="0.989723 0.974624 0.989723"/>
        </geometry>
      </visual>
      <collision name="col_mastcam_thermal_infrared_camera">
        <origin xyz="-0.040582 0 0.010122" rpy="0 0 0"/>
        <geometry>
          <box size="0.145984 0.052848 0.10211"/>
        </geometry>
      </collision>
    </link>

    <link name="male_connector_front">
      <inertial>
        <origin xyz="0 0 0" rpy="0 0 0"/>
        <mass value="0.001"/>
        <inertia ixx="0.001" ixy="0" ixz="0" iyy="0.001" iyz="0" izz="0.001"/>
      </inertial>
    </link>

    <link name="male_connector_left">
      <inertial>
        <origin xyz="0 0 0" rpy="0 0 0"/>
        <mass value="0.001"/>
        <inertia ixx="0.001" ixy="0" ixz="0" iyy="0.001" iyz="0" izz="0.001"/>
      </inertial>
    </link>

    <link name="male_connector_rear">
      <inertial>
        <origin xyz="0 0 0" rpy="0 0 0"/>
        <mass value="0.001"/>
        <inertia ixx="0.001" ixy="0" ixz="0" iyy="0.001" iyz="0" izz="0.001"/>
      </inertial>
    </link>

    <link name="male_connector_right">
      <inertial>
        <origin xyz="0 0 0" rpy="0 0 0"/>
        <mass value="0.001"/>
        <inertia ixx="0.001" ixy="0" ixz="0" iyy="0.001" iyz="0" izz="0.001"/>
      </inertial>
    </link>

    <link name="mast_link">
      <inertial>
        <origin xyz="0 0 0" rpy="0 0 0"/>
        <mass value="10.0"/>
        <inertia ixx="0.737241" ixy="0" ixz="0" iyy="0.737243" iyz="0" izz="0.737243"/>
      </inertial>
      <visual name="vis_High_Resolution_camera">
        <origin xyz="0.080936 -0.013687 0.443983" rpy="0 0 0"/>
        <geometry>
          <mesh filename="../meshes/stl/HRCam.stl" scale="0.989723 0.974624 0.989723"/>
        </geometry>
      </visual>
      <visual name="vis_mast">
        <origin xyz="0 0 0" rpy="0 0 0"/>
        <geometry>
          <mesh filename="../meshes/stl/mast.stl" scale="0.890963 0.995824 0.857055"/>
        </geometry>
      </visual>
      <collision name="col_mast">
        <origin xyz="-0.001506 -0.003576 0.022955" rpy="0 0 0"/>
        <geometry>
          <box size="0.058454 0.070621 1.260627"/>
        </geometry>
      </collision>
    </link>

    <link name="mastcam_ptu_pan_joint">
      <inertial>
        <origin xyz="0 0 0" rpy="0 0 0"/>
        <mass value="0.1"/>
        <inertia ixx="2e-06" ixy="0" ixz="0" iyy="2e-06" iyz="0" izz="2e-06"/>
      </inertial>
      <visual name="vis_mastcam_ptu_pan">
        <origin xyz="-0.033119 -0.006441 -0.000345" rpy="0 0 0"/>
        <geometry>
          <mesh filename="../meshes/stl/mastcam_ptu_pan.stl" scale="0.989723 0.974624 0.989723"/>
        </geometry>
      </visual>
      <collision name="col_mastcam_ptu_pan">
        <origin xyz="-0.031407 0.010423 0" rpy="0 0 0"/>
        <geometry>
          <box size="0.114583 0.059908 0.06835"/>
        </geometry>
      </collision>
    </link>

    <link name="mastcam_ptu_pan_joint_1">
      <inertial>
        <origin xyz="0 0 0" rpy="0 0 0"/>
        <mass value="0.1"/>
        <inertia ixx="2e-06" ixy="0" ixz="0" iyy="2e-06" iyz="0" izz="2e-06"/>
      </inertial>
      <visual name="vis_mastcam_ptu_pan_01">
        <origin xyz="0 0 1e-06" rpy="0 0 0"/>
        <geometry>
          <mesh filename="../meshes/stl/mastcam_ptu_pan_01.stl" scale="0.989723 0.974624 0.989723"/>
        </geometry>
      </visual>
      <collision name="col_mastcam_ptu_pan_01">
        <origin xyz="0 0.010825 -0.044812" rpy="0 0 0"/>
        <geometry>
          <box size="0.114583 0.138112 0.427795"/>
        </geometry>
      </collision>
    </link>

    <link name="mastcam_ptu_tilt_joint">
      <inertial>
        <origin xyz="0 0 0" rpy="0 0 0"/>
        <mass value="0.23112"/>
        <inertia ixx="2e-06" ixy="0" ixz="0" iyy="2e-06" iyz="0" izz="2e-06"/>
      </inertial>
      <visual name="vis_mastcam_ptu_tilt_bench">
        <origin xyz="0.003935 0.000413 0.018875" rpy="-1.570796 0 0"/>
        <geometry>
          <mesh filename="../meshes/stl/mastcam_ptu_camera_bench.stl" scale="0.989723 0.974624 0.989723"/>
        </geometry>
      </visual>
      <collision name="col_mastcam_ptu_tilt_bench">
        <origin xyz="0 0.011814 -0.005434" rpy="-1.570796 0 -1e-06"/>
        <geometry>
          <box size="0.050568 0.361335 0.059564"/>
        </geometry>
      </collision>
    </link>

    <link name="omega_front_left">
      <inertial>
        <origin xyz="0.000161 9.9e-05 -2.5e-05" rpy="0 0 0"/>
        <mass value="8.0"/>
        <inertia ixx="0.13886" ixy="0" ixz="0" iyy="0.13886" iyz="0" izz="0.13886"/>
      </inertial>
      <visual name="vis_wheel_3_front_left_HQ">
        <origin xyz="0 0 0" rpy="-1.478195 1.570794 -1.477541"/>
        <geometry>
          <mesh filename="../meshes/stl/wheel_outer.stl" scale="1.000001 1.000001 1.0"/>
        </geometry>
        <material name="mat_wheel_grey"/>
      </visual>
      <collision name="col_wheel_front_left">
        <origin xyz="0.000161 9.9e-05 -2.5e-05" rpy="0 0 0"/>
        <geometry>
          <sphere radius="0.195"/>
        </geometry>
      </collision>
    </link>

    <link name="omega_front_right">
      <inertial>
        <origin xyz="0.000161 0.0001 -2.5e-05" rpy="0 0 0"/>
        <mass value="8.0"/>
        <inertia ixx="0.13886" ixy="0" ixz="0" iyy="0.13886" iyz="0" izz="0.13886"/>
      </inertial>
      <visual name="vis_wheel_3_front_right_HQ">
        <origin xyz="0 0 0" rpy="1.470575 1.570794 1.491396"/>
        <geometry>
          <mesh filename="../meshes/stl/wheel_outer.stl" scale="1.0 1.000001 1.0"/>
        </geometry>
        <material name="mat_wheel_grey"/>
      </visual>
      <collision name="col_wheel_front_right">
        <origin xyz="0.000161 0.0001 -2.4e-05" rpy="0 0 0"/>
        <geometry>
          <sphere radius="0.195"/>
        </geometry>
      </collision>
    </link>

    <link name="omega_rear_left">
      <inertial>
        <origin xyz="0.000161 9.9e-05 0.000951" rpy="0 0 0"/>
        <mass value="8.0"/>
        <inertia ixx="0.13886" ixy="0" ixz="0" iyy="0.13886" iyz="0" izz="0.13886"/>
      </inertial>
      <visual name="vis_wheel_3_rear_left_HQ">
        <origin xyz="0 0 0" rpy="0 1.570796 0"/>
        <geometry>
          <mesh filename="../meshes/stl/wheel_outer.stl" scale="1.0 1.0 1.0"/>
        </geometry>
        <material name="mat_wheel_grey"/>
      </visual>
      <collision name="col_wheel_rear_left">
        <origin xyz="0.000161 9.8e-05 0.000953" rpy="0 0 0"/>
        <geometry>
          <sphere radius="0.195"/>
        </geometry>
      </collision>
    </link>

    <link name="omega_rear_right">
      <inertial>
        <origin xyz="0.000161 0.0001 -2.3e-05" rpy="0 0 0"/>
        <mass value="8.0"/>
        <inertia ixx="0.13886" ixy="0" ixz="0" iyy="0.13886" iyz="0" izz="0.13886"/>
      </inertial>
      <visual name="vis_wheel_3_rear_right_HQ">
        <origin xyz="0 0 0" rpy="0 1.570796 0"/>
        <geometry>
          <mesh filename="../meshes/stl/wheel_outer.stl" scale="1.0 1.0 1.0"/>
        </geometry>
        <material name="mat_wheel_grey"/>
      </visual>
      <collision name="col_wheel_rear_right">
        <origin xyz="0.000161 0.0001 -2.4e-05" rpy="0 0 0"/>
        <geometry>
          <sphere radius="0.195"/>
        </geometry>
      </collision>
    </link>

    <link name="phi_front_left">
      <inertial>
        <origin xyz="0.013452 -1e-06 0.054697" rpy="0 0 0"/>
        <mass value="2.62"/>
        <inertia ixx="0.00241" ixy="0" ixz="0" iyy="0.00241" iyz="0" izz="0.00138"/>
      </inertial>
      <visual name="vis_driveUnit_front_left_HQ">
        <origin xyz="0 0 0" rpy="0 0 -2e-06"/>
        <geometry>
          <mesh filename="../meshes/stl/driveUnit.stl" scale="1.0 1.0 1.0"/>
        </geometry>
        <material name="mat_grey_light"/>
      </visual>
      <collision name="col_driveUnit_front_left">
        <origin xyz="0.149135 -2e-06 0.258472" rpy="0 0 0"/>
        <geometry>
          <box size="0.056304 0.056304 0.088701"/>
        </geometry>
      </collision>
    </link>

    <link name="phi_front_right">
      <inertial>
        <origin xyz="0.013453 0 0.054697" rpy="0 0 0"/>
        <mass value="2.62"/>
        <inertia ixx="0.00241" ixy="0" ixz="0" iyy="0.00241" iyz="0" izz="0.00138"/>
      </inertial>
      <visual name="vis_driveUnit_front_right_HQ">
        <origin xyz="0 0 0" rpy="0 0 3e-06"/>
        <geometry>
          <mesh filename="../meshes/stl/driveUnit.stl" scale="1.0 1.000001 1.0"/>
        </geometry>
        <material name="mat_grey_light"/>
      </visual>
      <collision name="col_driveUnit_front_right">
        <origin xyz="0.149135 0 0.258471" rpy="0 0 0"/>
        <geometry>
          <box size="0.056304 0.056304 0.088701"/>
        </geometry>
      </collision>
    </link>

    <link name="phi_rear_left">
      <inertial>
        <origin xyz="0.013454 -2e-06 0.054697" rpy="0 0 0"/>
        <mass value="2.62"/>
        <inertia ixx="0.00241" ixy="0" ixz="0" iyy="0.00241" iyz="0" izz="0.00138"/>
      </inertial>
      <visual name="vis_driveUnit_rear_left_HQ">
        <origin xyz="0 0 0" rpy="0 0 0"/>
        <geometry>
          <mesh filename="../meshes/stl/driveUnit.stl" scale="1.0 1.0 1.0"/>
        </geometry>
        <material name="mat_grey_light"/>
      </visual>
      <collision name="col_driveUnit_rear_left">
        <origin xyz="0.149136 0 0.258472" rpy="0 0 0"/>
        <geometry>
          <box size="0.056304 0.056304 0.088701"/>
        </geometry>
      </collision>
    </link>

    <link name="phi_rear_right">
      <inertial>
        <origin xyz="0.013455 0 0.054697" rpy="0 0 0"/>
        <mass value="2.62"/>
        <inertia ixx="0.00241" ixy="0" ixz="0" iyy="0.00241" iyz="0" izz="0.00138"/>
      </inertial>
      <visual name="vis_driveUnit_rear_right_HQ">
        <origin xyz="0 0 0" rpy="0 0 0"/>
        <geometry>
          <mesh filename="../meshes/stl/driveUnit.stl" scale="1.0 1.0 1.0"/>
        </geometry>
        <material name="mat_grey_light"/>
      </visual>
      <collision name="col_driveUnit_rear_right">
        <origin xyz="0.149136 0 0.258472" rpy="-5e-06 -2e-06 0"/>
        <geometry>
          <box size="0.056304 0.056304 0.088701"/>
        </geometry>
      </collision>
    </link>

    <link name="sherpa_tt">
      <inertial>
        <origin xyz="0 0 0.011573" rpy="0 0 0"/>
        <mass value="25.799999"/>
        <inertia ixx="1.16805" ixy="0" ixz="0" iyy="1.16805" iyz="0" izz="1.97347"/>
      </inertial>
      <visual name="col_armHolder_front">
        <origin xyz="0.237737 -0.001489 0.155771" rpy="0 0.523599 0"/>
        <geometry>
          <box size="0.156033 0.156 0.154033"/>
        </geometry>
        <material name="mat_grey.001"/>
      </visual>
      <visual name="vis_armHolder_front_HQ">
        <origin xyz="0.237737 -0.001489 0.155771" rpy="0 0 0"/>
        <geometry>
          <mesh filename="../meshes/stl/armHolder.stl" scale="1.0 1.0 1.0"/>
        </geometry>
        <material name="mat_grey"/>
      </visual>
      <visual name="vis_armHolder_left_HQ">
        <origin xyz="-0.000627 0.239418 0.15748" rpy="0 0 1.570796"/>
        <geometry>
          <mesh filename="../meshes/stl/armHolder.stl" scale="1.0 1.0 1.0"/>
        </geometry>
        <material name="mat_grey"/>
      </visual>
      <visual name="vis_armHolder_rear_HQ">
        <origin xyz="-0.240045 0 0.15748" rpy="0 0 3.141593"/>
        <geometry>
          <mesh filename="../meshes/stl/armHolder1.stl" scale="1.0 1.0 1.0"/>
        </geometry>
        <material name="mat_grey"/>
      </visual>
      <visual name="vis_armHolder_right_HQ">
        <origin xyz="-0.000627 -0.239418 0.15748" rpy="0 0 -1.570796"/>
        <geometry>
          <mesh filename="../meshes/stl/armHolder.stl" scale="1.0 1.0 1.0"/>
        </geometry>
        <material name="mat_grey"/>
      </visual>
      <visual name="vis_body_HQ">
        <origin xyz="-0.001267 -0.000581 0.030579" rpy="0 0 0"/>
        <geometry>
          <mesh filename="../meshes/stl/body.stl" scale="1.0 1.0 1.0"/>
        </geometry>
        <material name="Yellow"/>
      </visual>
      <visual name="visual_connectors.001">
        <origin xyz="0 0 0" rpy="0 0 0"/>
        <geometry>
          <mesh filename="../meshes/stl/connectors.stl" scale="0.5 0.5 0.5"/>
        </geometry>
        <material name="connector"/>
      </visual>
      <collision name="col_armHolder_left">
        <origin xyz="-0.000627 0.239418 0.15748" rpy="0 0.523599 1.570796"/>
        <geometry>
          <box size="0.156033 0.156 0.154033"/>
        </geometry>
      </collision>
      <collision name="col_armHolder_rear">
        <origin xyz="-0.240045 0 0.15748" rpy="0 0 3.141593"/>
        <geometry>
          <box size="0.292416 0.156 0.350479"/>
        </geometry>
      </collision>
      <collision name="col_armHolder_right">
        <origin xyz="-0.000627 -0.239418 0.15748" rpy="0 0.523599 -1.570796"/>
        <geometry>
          <box size="0.156033 0.156 0.154033"/>
        </geometry>
      </collision>
      <collision name="col_body">
        <origin xyz="0 0 -0.026488" rpy="0 0 0"/>
        <geometry>
          <box size="0.677455 0.677455 0.226166"/>
        </geometry>
      </collision>
      <collision name="collision_body_1">
        <origin xyz="0.16348 -0.164088 0.219741" rpy="0 -0.610865 2.356194"/>
        <geometry>
          <box size="0.503254 0.086066 0.039236"/>
        </geometry>
      </collision>
      <collision name="collision_body_2">
        <origin xyz="-0.164088 -0.16348 0.219741" rpy="0 -0.610865 0.785398"/>
        <geometry>
          <box size="0.503254 0.086066 0.039236"/>
        </geometry>
      </collision>
      <collision name="collision_body_3">
        <origin xyz="-0.16348 0.164088 0.219741" rpy="0 -0.610865 -0.785398"/>
        <geometry>
          <box size="0.503254 0.086066 0.039236"/>
        </geometry>
      </collision>
      <collision name="collision_body_4">
        <origin xyz="0.164088 0.16348 0.219741" rpy="0 -0.610865 -2.356194"/>
        <geometry>
          <box size="0.503254 0.086066 0.039236"/>
        </geometry>
      </collision>
    </link>

    <joint name="alpha_front_left" type="revolute">
      <origin xyz="0.4 0.4 0" rpy="0 0 0.7854"/>
      <parent link="sherpa_tt"/>
      <child link="alpha_front_left"/>
      <axis xyz="0 0 1.0"/>
      <limit lower="-1.570796" upper="2.181662" effort="0" velocity="0.087266"/>
    </joint>

    <joint name="alpha_front_right" type="revolute">
      <origin xyz="0.4 -0.4 0" rpy="0 0 -0.7854"/>
      <parent link="sherpa_tt"/>
      <child link="alpha_front_right"/>
      <axis xyz="0 0 1.0"/>
      <limit lower="-1.570796" upper="2.181662" effort="1" velocity="0.087266"/>
    </joint>

    <joint name="alpha_rear_left" type="revolute">
      <origin xyz="-0.4 0.4 0" rpy="0 0 2.356194"/>
      <parent link="sherpa_tt"/>
      <child link="alpha_rear_left"/>
      <axis xyz="0 0 1.0"/>
      <limit lower="-1.570796" upper="2.181662" effort="0" velocity="0.087266"/>
    </joint>

    <joint name="alpha_rear_right" type="revolute">
      <origin xyz="-0.4 -0.4 0" rpy="0 0 -2.356194"/>
      <parent link="sherpa_tt"/>
      <child link="alpha_rear_right"/>
      <axis xyz="0 0 1.0"/>
      <limit lower="-1.570796" upper="2.181662" effort="0" velocity="0.087266"/>
    </joint>

    <joint name="arm_joint_1" type="revolute">
      <origin xyz="0 0 0.302057" rpy="-3.141591 0 0"/>
      <parent link="sherpa_tt"/>
      <child link="arm_joint_1"/>
      <axis xyz="0 0 -1.0"/>
      <limit lower="-3.141593" upper="3.141593" effort="0" velocity="0"/>
    </joint>

    <joint name="arm_joint_2" type="revolute">
      <origin xyz="0.224955 6.4e-05 -0.207556" rpy="1.570795 0 -0.004909"/>
      <parent link="arm_joint_1"/>
      <child link="arm_joint_2"/>
      <axis xyz="0 0.01756 0.999846"/>
      <limit lower="-3.141593" upper="3.141593" effort="0" velocity="0"/>
    </joint>

    <joint name="arm_joint_3" type="revolute">
      <origin xyz="0.734901 0.030008 6.4e-05" rpy="0 0 1e-06"/>
      <parent link="arm_joint_2"/>
      <child link="arm_joint_3"/>
      <axis xyz="2e-06 0 1.0"/>
      <limit lower="-3.141593" upper="3.141593" effort="0" velocity="0"/>
    </joint>

    <joint name="arm_joint_4" type="revolute">
      <origin xyz="0.693951 -0.029808 9.1e-05" rpy="-1.570796 0 -1.570797"/>
      <parent link="arm_joint_3"/>
      <child link="arm_joint_4"/>
      <axis xyz="0 0 1.0"/>
      <limit lower="-3.141593" upper="3.141593" effort="0" velocity="0"/>
    </joint>

    <joint name="arm_joint_5" type="revolute">
      <origin xyz="-0.00136 -0.00323 0" rpy="1.570798 -1.570796 0"/>
      <parent link="arm_joint_4"/>
      <child link="arm_joint_5"/>
      <axis xyz="0 0 1.0"/>
      <limit lower="-3.141593" upper="3.141593" effort="0" velocity="0"/>
    </joint>

    <joint name="arm_joint_6" type="revolute">
      <origin xyz="0.302575 -0.00176 -0.005895" rpy="-1.570797 -1e-06 -1.570796"/>
      <parent link="arm_joint_5"/>
      <child link="arm_joint_6"/>
      <axis xyz="0 0 1.0"/>
      <limit lower="-3.141593" upper="3.141593" effort="0" velocity="0"/>
    </joint>

    <joint name="avionics_box_link" type="fixed">
      <origin xyz="0.572975 -0.007043 0.020231" rpy="0 0 0"/>
      <parent link="sherpa_tt"/>
      <child link="avionics_box_link"/>
    </joint>

    <joint name="beta1_fake_front_left" type="revolute">
      <origin xyz="0.4 0 0" rpy="0 0 0"/>
      <parent link="beta_front_left"/>
      <child link="beta1_fake_front_left"/>
      <axis xyz="0 0 1.0"/>
      <limit lower="-0.296706" upper="0.872665" effort="0" velocity="0.174533"/>
    </joint>

    <joint name="beta1_fake_front_right" type="revolute">
      <origin xyz="0.4 0 0" rpy="0 0 0"/>
      <parent link="beta_front_right"/>
      <child link="beta1_fake_front_right"/>
      <axis xyz="0 0 1.0"/>
      <limit lower="-0.296706" upper="0.872665" effort="0" velocity="0.174533"/>
    </joint>

    <joint name="beta1_fake_rear_left" type="revolute">
      <origin xyz="0.4 0 0" rpy="0 1e-06 0"/>
      <parent link="beta_rear_left"/>
      <child link="beta1_fake_rear_left"/>
      <axis xyz="0 0 1.0"/>
      <limit lower="-0.296706" upper="0.872665" effort="0" velocity="0.174533"/>
    </joint>

    <joint name="beta1_fake_rear_right" type="revolute">
      <origin xyz="0.4 0 0" rpy="0 0 0"/>
      <parent link="beta_rear_right"/>
      <child link="beta1_fake_rear_right"/>
      <axis xyz="0 0 1.0"/>
      <limit lower="-0.296706" upper="0.872665" effort="0" velocity="0.174533"/>
    </joint>

    <joint name="beta2_fake_front_left" type="revolute">
      <origin xyz="0.05 0 0.15155" rpy="-1.570796 0 0"/>
      <parent link="alpha_front_left"/>
      <child link="beta2_fake_front_left"/>
      <axis xyz="0 0 1.0"/>
      <limit lower="-0.872665" upper="0.296706" effort="0" velocity="0.174533"/>
    </joint>

    <joint name="beta2_fake_front_right" type="revolute">
      <origin xyz="0.05 0 0.15155" rpy="-1.570796 0 0"/>
      <parent link="alpha_front_right"/>
      <child link="beta2_fake_front_right"/>
      <axis xyz="0 0 1.0"/>
      <limit lower="-0.872665" upper="0.296706" effort="0" velocity="0.174533"/>
    </joint>

    <joint name="beta2_fake_rear_left" type="revolute">
      <origin xyz="0.05 0 0.15155" rpy="-1.570796 0 0"/>
      <parent link="alpha_rear_left"/>
      <child link="beta2_fake_rear_left"/>
      <axis xyz="0 0 1.0"/>
      <limit lower="-0.872665" upper="0.296706" effort="0" velocity="0.174533"/>
    </joint>

    <joint name="beta2_fake_rear_right" type="revolute">
      <origin xyz="0.05 0 0.15155" rpy="-1.570796 0 0"/>
      <parent link="alpha_rear_right"/>
      <child link="beta2_fake_rear_right"/>
      <axis xyz="0 0 1.0"/>
      <limit lower="-0.872665" upper="0.296706" effort="0" velocity="0.174533"/>
    </joint>

    <joint name="beta_front_left" type="revolute">
      <origin xyz="0.1375 0 0" rpy="-1.570796 0 0"/>
      <parent link="alpha_front_left"/>
      <child link="beta_front_left"/>
      <axis xyz="0 0 1.0"/>
      <limit lower="-0.872665" upper="0.296706" effort="0" velocity="0.174533"/>
    </joint>

    <joint name="beta_front_right" type="revolute">
      <origin xyz="0.1375 0 0" rpy="-1.570796 0 0"/>
      <parent link="alpha_front_right"/>
      <child link="beta_front_right"/>
      <axis xyz="0 0 1.0"/>
      <limit lower="-0.872665" upper="0.296706" effort="0" velocity="0.174533"/>
    </joint>

    <joint name="beta_rear_left" type="revolute">
      <origin xyz="0.1375 0 0" rpy="-1.570796 0 0"/>
      <parent link="alpha_rear_left"/>
      <child link="beta_rear_left"/>
      <axis xyz="0 0 1.0"/>
      <limit lower="-0.872665" upper="0.296706" effort="0" velocity="0.174533"/>
    </joint>

    <joint name="beta_rear_right" type="revolute">
      <origin xyz="0.1375 0 0" rpy="-1.570796 0 0"/>
      <parent link="alpha_rear_right"/>
      <child link="beta_rear_right"/>
      <axis xyz="0 0 1.0"/>
      <limit lower="-0.872665" upper="0.296706" effort="0" velocity="0.174533"/>
    </joint>

    <joint name="endeffector_camera" type="fixed">
      <origin xyz="-0.020508 -0.021587 0" rpy="0.785398 -1.570796 0"/>
      <parent link="arm_joint_6"/>
      <child link="endeffector_camera"/>
    </joint>

    <joint name="force_torque_sensor_front_left" type="fixed">
      <origin xyz="0.1 0 0" rpy="0 0 0"/>
      <parent link="phi_front_left"/>
      <child link="link_force_torque_sensor_link_front_left"/>
    </joint>

    <joint name="force_torque_sensor_front_right" type="fixed">
      <origin xyz="0.1 0 0" rpy="0 0 0"/>
      <parent link="phi_front_right"/>
      <child link="link_force_torque_sensor_link_front_right"/>
    </joint>

    <joint name="force_torque_sensor_rear_left" type="fixed">
      <origin xyz="0.1 0 0" rpy="0 0 0"/>
      <parent link="phi_rear_left"/>
      <child link="link_force_torque_sensor_link_rear_left"/>
    </joint>

    <joint name="force_torque_sensor_rear_right" type="fixed">
      <origin xyz="0.100001 0 0" rpy="0 0 0"/>
      <parent link="phi_rear_right"/>
      <child link="link_force_torque_sensor_link_rear_right"/>
    </joint>

    <joint name="gamma1_fake_front_left" type="revolute">
      <origin xyz="0.396596 0.052072 0" rpy="0 0 0"/>
      <parent link="gamma_front_left"/>
      <child link="gamma1_fake_front_left"/>
      <axis xyz="0 0 1.0"/>
      <limit lower="-1.308997" upper="0.017453" effort="0" velocity="0.087266"/>
    </joint>

    <joint name="gamma1_fake_front_right" type="revolute">
      <origin xyz="0.396596 0.052072 0" rpy="0 0 0"/>
      <parent link="gamma_front_right"/>
      <child link="gamma1_fake_front_right"/>
      <axis xyz="0 0 1.0"/>
      <limit lower="-1.308997" upper="0.017453" effort="0" velocity="0.087266"/>
    </joint>

    <joint name="gamma1_fake_rear_left" type="revolute">
      <origin xyz="0.396596 0.052072 0" rpy="0 0 0"/>
      <parent link="gamma_rear_left"/>
      <child link="gamma1_fake_rear_left"/>
      <axis xyz="0 0 1.0"/>
      <limit lower="-1.308997" upper="0.017453" effort="0" velocity="0.087266"/>
    </joint>

    <joint name="gamma1_fake_rear_right" type="revolute">
      <origin xyz="0.396595 0.052072 0" rpy="0 0 0"/>
      <parent link="gamma_rear_right"/>
      <child link="gamma1_fake_rear_right"/>
      <axis xyz="0 0 1.0"/>
      <limit lower="-1.308997" upper="0.017453" effort="0" velocity="0.087266"/>
    </joint>

    <joint name="gamma2_fake_front_left" type="revolute">
      <origin xyz="0.13 -0.127 0" rpy="0 0 0.13055"/>
      <parent link="beta1_fake_front_left"/>
      <child link="gamma2_fake_front_left"/>
      <axis xyz="0 0 1.0"/>
      <limit lower="-0.017453" upper="1.308997" effort="0" velocity="0.087266"/>
    </joint>

    <joint name="gamma2_fake_front_right" type="revolute">
      <origin xyz="0.13 -0.127 0" rpy="0 0 0.13055"/>
      <parent link="beta1_fake_front_right"/>
      <child link="gamma2_fake_front_right"/>
      <axis xyz="0 0 1.0"/>
      <limit lower="-0.017453" upper="1.308997" effort="0" velocity="0.087266"/>
    </joint>

    <joint name="gamma2_fake_rear_left" type="revolute">
      <origin xyz="0.13 -0.127 0" rpy="0 0 0.13055"/>
      <parent link="beta1_fake_rear_left"/>
      <child link="gamma2_fake_rear_left"/>
      <axis xyz="0 0 1.0"/>
      <limit lower="-0.017453" upper="1.308997" effort="0" velocity="0.087266"/>
    </joint>

    <joint name="gamma2_fake_rear_right" type="revolute">
      <origin xyz="0.13 -0.127 0" rpy="0 0 0.13055"/>
      <parent link="beta1_fake_rear_right"/>
      <child link="gamma2_fake_rear_right"/>
      <axis xyz="0 0 1.0"/>
      <limit lower="-0.017453" upper="1.308997" effort="0" velocity="0.087266"/>
    </joint>

    <joint name="gamma_front_left" type="revolute">
      <origin xyz="0.045 0 0" rpy="0 0 0"/>
      <parent link="beta1_fake_front_left"/>
      <child link="gamma_front_left"/>
      <axis xyz="0 0 1.0"/>
      <limit lower="-0.017453" upper="1.308997" effort="0" velocity="0.087266"/>
    </joint>

    <joint name="gamma_front_right" type="revolute">
      <origin xyz="0.045 0 0" rpy="0 0 0"/>
      <parent link="beta1_fake_front_right"/>
      <child link="gamma_front_right"/>
      <axis xyz="0 0 1.0"/>
      <limit lower="-0.017453" upper="1.308997" effort="0" velocity="0.087266"/>
    </joint>

    <joint name="gamma_rear_left" type="revolute">
      <origin xyz="0.045 0 0" rpy="0 0 0"/>
      <parent link="beta1_fake_rear_left"/>
      <child link="gamma_rear_left"/>
      <axis xyz="0 0 1.0"/>
      <limit lower="-0.017453" upper="1.308997" effort="0" velocity="0.087266"/>
    </joint>

    <joint name="gamma_rear_right" type="revolute">
      <origin xyz="0.045 0 0" rpy="0 0 0"/>
      <parent link="beta1_fake_rear_right"/>
      <child link="gamma_rear_right"/>
      <axis xyz="0 0 1.0"/>
      <limit lower="-0.017453" upper="1.308997" effort="0" velocity="0.087266"/>
    </joint>

    <joint name="generator_link" type="fixed">
      <origin xyz="-0.486981 -0.001715 0.075941" rpy="0 0 0"/>
      <parent link="sherpa_tt"/>
      <child link="generator_link"/>
    </joint>

    <joint name="gps_antenna_link" type="fixed">
      <origin xyz="-0.29209 -0.000104 0.409711" rpy="0 0 0"/>
      <parent link="sherpa_tt"/>
      <child link="gps_antenna_link"/>
    </joint>

    <joint name="imu" type="fixed">
      <origin xyz="0 0 0.011573" rpy="0 0 0"/>
      <parent link="sherpa_tt"/>
      <child link="imu"/>
    </joint>

    <joint name="joint_velodyne" type="fixed">
      <origin xyz="-0.135931 0 -0.181582" rpy="3.141591 0 0"/>
      <parent link="arm_joint_1"/>
      <child link="joint_velodyne"/>
    </joint>

    <joint name="link_ft_arm" type="fixed">
      <origin xyz="-0.001192 0.001544 -0.073077" rpy="0 0 0"/>
      <parent link="arm_joint_6"/>
      <child link="link_ft_arm"/>
    </joint>

    <joint name="link_gps_antenna_1" type="fixed">
      <origin xyz="0 -0.638136 0.023643" rpy="0 0 0"/>
      <parent link="gps_antenna_link"/>
      <child link="link_gps_antenna_1"/>
    </joint>

    <joint name="link_gps_antenna_2" type="fixed">
      <origin xyz="0 0.639397 0.023643" rpy="0 0 0"/>
      <parent link="gps_antenna_link"/>
      <child link="link_gps_antenna_2"/>
    </joint>

    <joint name="link_mast_box" type="fixed">
      <origin xyz="0.072374 0.00319 -0.00613" rpy="0 0 0"/>
      <parent link="mast_link"/>
      <child link="link_mast_box"/>
    </joint>

    <joint name="link_mastcam_fixed_cameras" type="fixed">
      <origin xyz="0.268692 0.014763 -0.213947" rpy="0 0 0"/>
      <parent link="mast_link"/>
      <child link="link_mastcam_fixed_cameras"/>
    </joint>

    <joint name="link_mastcam_fixed_left" type="fixed">
      <origin xyz="0.044616 0.063151 0.008704" rpy="0 0 0"/>
      <parent link="link_mastcam_fixed_cameras"/>
      <child link="link_mastcam_fixed_left"/>
    </joint>

    <joint name="link_mastcam_fixed_right" type="fixed">
      <origin xyz="0.041951 -0.07901 0.009186" rpy="0 0 0"/>
      <parent link="link_mastcam_fixed_cameras"/>
      <child link="link_mastcam_fixed_right"/>
    </joint>

    <joint name="link_mastcam_ptu_left" type="fixed">
      <origin xyz="0.094836 0.055678 -0.193848" rpy="-1.570796 0 0"/>
      <parent link="mastcam_ptu_tilt_joint"/>
      <child link="link_mastcam_ptu_left"/>
    </joint>

    <joint name="link_mastcam_ptu_right" type="fixed">
      <origin xyz="0.088467 0.055678 0.138802" rpy="-1.570796 0 0"/>
      <parent link="mastcam_ptu_tilt_joint"/>
      <child link="link_mastcam_ptu_right"/>
    </joint>

    <joint name="link_mastcam_thermal_infrared" type="fixed">
      <origin xyz="0.136852 -0.009619 0.246513" rpy="0 0 0"/>
      <parent link="mast_link"/>
      <child link="link_mastcam_thermal_infrared"/>
    </joint>

    <joint name="male_connector_front" type="fixed">
      <origin xyz="0.199237 -0.001489 0.089087" rpy="0 0.610865 0"/>
      <parent link="sherpa_tt"/>
      <child link="male_connector_front"/>
    </joint>

    <joint name="male_connector_left" type="fixed">
      <origin xyz="-0.000627 0.200918 0.090796" rpy="0 0.610865 1.570796"/>
      <parent link="sherpa_tt"/>
      <child link="male_connector_left"/>
    </joint>

    <joint name="male_connector_rear" type="fixed">
      <origin xyz="-0.201545 0 0.090796" rpy="0 0.610865 -3.141592"/>
      <parent link="sherpa_tt"/>
      <child link="male_connector_rear"/>
    </joint>

    <joint name="male_connector_right" type="fixed">
      <origin xyz="-0.000627 -0.200918 0.090796" rpy="0 0.610865 -1.570796"/>
      <parent link="sherpa_tt"/>
      <child link="male_connector_right"/>
    </joint>

    <joint name="mast_link" type="fixed">
      <origin xyz="-0.169007 0.001389 0.448801" rpy="0 0 0"/>
      <parent link="avionics_box_link"/>
      <child link="mast_link"/>
    </joint>

    <joint name="mastcam_ptu_pan_joint" type="revolute">
      <origin xyz="0.005257 -0.022543 0.735898" rpy="0 0 0"/>
      <parent link="mast_link"/>
      <child link="mastcam_ptu_pan_joint"/>
      <axis xyz="0 0 1.0"/>
      <limit lower="-3.14159" upper="3.14159" effort="0" velocity="0"/>
    </joint>

    <joint name="mastcam_ptu_pan_joint_1" type="fixed">
      <origin xyz="-0.027783 -0.015434 0.677528" rpy="0 0 0"/>
      <parent link="mast_link"/>
      <child link="mastcam_ptu_pan_joint_1"/>
    </joint>

    <joint name="mastcam_ptu_tilt_joint" type="revolute">
      <origin xyz="0.000166 -0.012809 0.017802" rpy="1.570796 0 0"/>
      <parent link="mastcam_ptu_pan_joint"/>
      <child link="mastcam_ptu_tilt_joint"/>
      <axis xyz="0 0 1.0"/>
      <limit lower="-1.102175" upper="1.102175" effort="0" velocity="0"/>
    </joint>

    <joint name="omega_front_left" type="continuous">
      <origin xyz="-0.1 0 0" rpy="0 -1.570796 0"/>
      <parent link="link_force_torque_sensor_link_front_left"/>
      <child link="omega_front_left"/>
      <axis xyz="0 0 -1.0"/>
      <limit effort="1000.0" velocity="0.785"/>
    </joint>

    <joint name="omega_front_right" type="continuous">
      <origin xyz="-0.1 0 0" rpy="0 -1.570796 0"/>
      <parent link="link_force_torque_sensor_link_front_right"/>
      <child link="omega_front_right"/>
      <axis xyz="0 0 -1.0"/>
      <limit effort="1000.0" velocity="0.785"/>
    </joint>

    <joint name="omega_rear_left" type="continuous">
      <origin xyz="-0.100977 0 0" rpy="0 -1.570796 0"/>
      <parent link="link_force_torque_sensor_link_rear_left"/>
      <child link="omega_rear_left"/>
      <axis xyz="0 0 -1.0"/>
      <limit effort="1000.0" velocity="0.785"/>
    </joint>

    <joint name="omega_rear_right" type="continuous">
      <origin xyz="-0.100001 0 0" rpy="0 -1.570796 0"/>
      <parent link="link_force_torque_sensor_link_rear_right"/>
      <child link="omega_rear_right"/>
      <axis xyz="0 0 -1.0"/>
      <limit effort="1000.0" velocity="0.785"/>
    </joint>

    <joint name="phi_front_left" type="revolute">
      <origin xyz="0.04302 0.355 0" rpy="1.570796 0 0"/>
      <parent link="gamma1_fake_front_left"/>
      <child link="phi_front_left"/>
      <axis xyz="0 0 1.0"/>
      <limit lower="-2.879793" upper="2.879793" effort="0" velocity="0.436332"/>
    </joint>

    <joint name="phi_front_right" type="revolute">
      <origin xyz="0.04302 0.355 0" rpy="1.570796 0 0"/>
      <parent link="gamma1_fake_front_right"/>
      <child link="phi_front_right"/>
      <axis xyz="0 0 1.0"/>
      <limit lower="-2.879793" upper="2.879793" effort="0" velocity="0.436332"/>
    </joint>

    <joint name="phi_rear_left" type="revolute">
      <origin xyz="0.04302 0.355 0" rpy="1.570796 0 0"/>
      <parent link="gamma1_fake_rear_left"/>
      <child link="phi_rear_left"/>
      <axis xyz="0 0 1.0"/>
      <limit lower="-2.879793" upper="2.879793" effort="0" velocity="0.436332"/>
    </joint>

    <joint name="phi_rear_right" type="revolute">
      <origin xyz="0.04302 0.355 0" rpy="1.570796 0 0"/>
      <parent link="gamma1_fake_rear_right"/>
      <child link="phi_rear_right"/>
      <axis xyz="0 0 1.0"/>
      <limit lower="-2.879793" upper="2.879793" effort="0" velocity="0.436332"/>
    </joint>

    <material name="Orange.003">
      <color rgba="0.5267 0.229953 0.00929 1.0"/>
    </material>

    <material name="Orange.004">
      <color rgba="0.5267 0.229953 0.00929 1.0"/>
    </material>

    <material name="Yellow">
      <color rgba="0.64 0.622065 0.026908 1.0"/>
    </material>

    <material name="connector">
      <color rgba="0.64 0.64 0.64 1.0"/>
    </material>

    <material name="mat_black">
      <color rgba="0.102589 0.102589 0.102589 1.0"/>
    </material>

    <material name="mat_grey">
      <color rgba="0.413818 0.391377 0.386162 1.0"/>
    </material>

    <material name="mat_grey.001">
      <color rgba="0.64052 0.605366 0.597199 1.0"/>
    </material>

    <material name="mat_grey_light">
      <color rgba="0.233012 0.233012 0.233012 1.0"/>
    </material>

    <material name="mat_wheel_grey">
      <color rgba="0.64052 0.605366 0.597199 1.0"/>
    </material>

    <material name="red">
      <color rgba="1.0 0 0 1.0"/>
    </material>

  </robot>
